<?xml version='1.0' encoding='utf-8'?>
<mujoco model="franka_pick_place">
  <compiler angle="radian" />
  <asset>
    <material name="white" rgba="1 1 1 1" specular="0.5" shininess="0.25" />
    <material name="off_white" rgba="0.901961 0.921569 0.929412 1" specular="0.5" shininess="0.25" />
    <material name="black" rgba="0.25 0.25 0.25 1" specular="0.5" shininess="0.25" />
    <material name="green" rgba="0 1 0 1" specular="0.5" shininess="0.25" />
    <material name="light_blue" rgba="0.039216 0.541176 0.780392 1" specular="0.5" shininess="0.25" />
    <material name="table_mat" rgba="0.38 0.30 0.18 1" />
    <material name="cube_mat" rgba="0.0 1.0 0.0 1" />
    <material name="target_floor_mat" rgba="0.72 0.70 0.62 1" />
    <material name="target_wall_mat" rgba="0.55 0.43 0.28 1" />

    <mesh name="link0_c" file="asset/link0.stl" />
    <mesh name="link1_c" file="asset/link1.stl" />
    <mesh name="link2_c" file="asset/link2.stl" />
    <mesh name="link3_c" file="asset/link3.stl" />
    <mesh name="link4_c" file="asset/link4.stl" />
    <mesh name="link5_c0" file="asset/link5_collision_0.obj" />
    <mesh name="link5_c1" file="asset/link5_collision_1.obj" />
    <mesh name="link5_c2" file="asset/link5_collision_2.obj" />
    <mesh name="link6_c" file="asset/link6.stl" />
    <mesh name="link7_c" file="asset/link7.stl" />
    <mesh name="hand_c" file="asset/hand.stl" />

    <mesh name="link0_0" file="asset/link0_0.obj" />
    <mesh name="link0_1" file="asset/link0_1.obj" />
    <mesh name="link0_2" file="asset/link0_2.obj" />
    <mesh name="link0_3" file="asset/link0_3.obj" />
    <mesh name="link0_4" file="asset/link0_4.obj" />
    <mesh name="link0_5" file="asset/link0_5.obj" />
    <mesh name="link0_7" file="asset/link0_7.obj" />
    <mesh name="link0_8" file="asset/link0_8.obj" />
    <mesh name="link0_9" file="asset/link0_9.obj" />
    <mesh name="link0_10" file="asset/link0_10.obj" />
    <mesh name="link0_11" file="asset/link0_11.obj" />
    <mesh name="link1_v" file="asset/link1.obj" />
    <mesh name="link2_v" file="asset/link2.obj" />
    <mesh name="link3_0" file="asset/link3_0.obj" />
    <mesh name="link3_1" file="asset/link3_1.obj" />
    <mesh name="link3_2" file="asset/link3_2.obj" />
    <mesh name="link3_3" file="asset/link3_3.obj" />
    <mesh name="link4_0" file="asset/link4_0.obj" />
    <mesh name="link4_1" file="asset/link4_1.obj" />
    <mesh name="link4_2" file="asset/link4_2.obj" />
    <mesh name="link4_3" file="asset/link4_3.obj" />
    <mesh name="link5_0" file="asset/link5_0.obj" />
    <mesh name="link5_1" file="asset/link5_1.obj" />
    <mesh name="link5_2" file="asset/link5_2.obj" />
    <mesh name="link6_0" file="asset/link6_0.obj" />
    <mesh name="link6_1" file="asset/link6_1.obj" />
    <mesh name="link6_2" file="asset/link6_2.obj" />
    <mesh name="link6_3" file="asset/link6_3.obj" />
    <mesh name="link6_4" file="asset/link6_4.obj" />
    <mesh name="link6_5" file="asset/link6_5.obj" />
    <mesh name="link6_6" file="asset/link6_6.obj" />
    <mesh name="link6_7" file="asset/link6_7.obj" />
    <mesh name="link6_8" file="asset/link6_8.obj" />
    <mesh name="link6_9" file="asset/link6_9.obj" />
    <mesh name="link6_10" file="asset/link6_10.obj" />
    <mesh name="link6_11" file="asset/link6_11.obj" />
    <mesh name="link6_12" file="asset/link6_12.obj" />
    <mesh name="link6_13" file="asset/link6_13.obj" />
    <mesh name="link6_14" file="asset/link6_14.obj" />
    <mesh name="link6_15" file="asset/link6_15.obj" />
    <mesh name="link6_16" file="asset/link6_16.obj" />
    <mesh name="link7_0" file="asset/link7_0.obj" />
    <mesh name="link7_1" file="asset/link7_1.obj" />
    <mesh name="link7_2" file="asset/link7_2.obj" />
    <mesh name="link7_3" file="asset/link7_3.obj" />
    <mesh name="link7_4" file="asset/link7_4.obj" />
    <mesh name="link7_5" file="asset/link7_5.obj" />
    <mesh name="link7_6" file="asset/link7_6.obj" />
    <mesh name="link7_7" file="asset/link7_7.obj" />
    <mesh name="hand_0" file="asset/hand_0.obj" />
    <mesh name="hand_1" file="asset/hand_1.obj" />
    <mesh name="hand_2" file="asset/hand_2.obj" />
    <mesh name="hand_3" file="asset/hand_3.obj" />
    <mesh name="hand_4" file="asset/hand_4.obj" />
    <mesh name="finger_0" file="asset/finger_0.obj" />
    <mesh name="finger_1" file="asset/finger_1.obj" />
  </asset>
  <worldbody>
    <geom type="mesh" mesh="link0_0" material="off_white" contype="0" conaffinity="0" />
    <geom type="mesh" mesh="link0_1" material="black" contype="0" conaffinity="0" />
    <geom type="mesh" mesh="link0_2" material="off_white" contype="0" conaffinity="0" />
    <geom type="mesh" mesh="link0_3" material="black" contype="0" conaffinity="0" />
    <geom type="mesh" mesh="link0_4" material="off_white" contype="0" conaffinity="0" />
    <geom type="mesh" mesh="link0_5" material="black" contype="0" conaffinity="0" />
    <geom type="mesh" mesh="link0_7" material="white" contype="0" conaffinity="0" />
    <geom type="mesh" mesh="link0_8" material="white" contype="0" conaffinity="0" />
    <geom type="mesh" mesh="link0_9" material="black" contype="0" conaffinity="0" />
    <geom type="mesh" mesh="link0_10" material="off_white" contype="0" conaffinity="0" />
    <geom type="mesh" mesh="link0_11" material="white" contype="0" conaffinity="0" />
    <geom type="mesh" mesh="link0_c" contype="0" conaffinity="0" rgba="1 1 1 0" group="1" />
    <body name="panda_link1" pos="0 0 0.333">
      <inertial pos="0.003875 0.002081 -0.04762" quat="0.711549 0.00634377 -0.0131124 0.702485" mass="4.97068" diaginertia="0.707137 0.703435 0.00852456" />
      <joint name="panda_joint1" pos="0 0 0" axis="0 0 1" range="-2.8973 2.8973" actuatorfrcrange="-87 87" damping="4" armature="0" />
      <geom type="mesh" mesh="link1_v" material="white" contype="0" conaffinity="0" />
      <geom type="mesh" mesh="link1_c" rgba="1 1 1 0" group="1" />
      <body name="panda_link2" quat="0.707107 -0.707107 0 0">
        <inertial pos="-0.003141 -0.02872 0.003495" quat="-0.168175 0.828366 -0.122878 0.520027" mass="0.646926" diaginertia="0.0310326 0.0283001 0.00273425" />
        <joint name="panda_joint2" pos="0 0 0" axis="0 0 1" range="-1.7628 1.7628" actuatorfrcrange="-87 87" damping="4" armature="0" />
        <geom type="mesh" mesh="link2_v" material="white" contype="0" conaffinity="0" />
        <geom type="mesh" mesh="link2_c" rgba="1 1 1 0" group="1" />
        <body name="panda_link3" pos="0 -0.316 0" quat="0.707107 0.707107 0 0">
          <inertial pos="0.027518 0.039252 -0.066502" quat="0.662769 -0.00678331 0.252053 0.705096" mass="3.2286" diaginertia="0.0415014 0.0414793 0.00124635" />
          <joint name="panda_joint3" pos="0 0 0" axis="0 0 1" range="-2.8973 2.8973" actuatorfrcrange="-87 87" damping="4" armature="0" />
          <geom type="mesh" mesh="link3_0" material="white" contype="0" conaffinity="0" />
          <geom type="mesh" mesh="link3_1" material="white" contype="0" conaffinity="0" />
          <geom type="mesh" mesh="link3_2" material="white" contype="0" conaffinity="0" />
          <geom type="mesh" mesh="link3_3" material="black" contype="0" conaffinity="0" />
          <geom type="mesh" mesh="link3_c" rgba="1 1 1 0" group="1" />
          <body name="panda_link4" pos="0.0825 0 0" quat="0.707107 0.707107 0 0">
            <inertial pos="-0.05317 0.104419 0.027454" quat="0.65058 0.529822 -0.0962034 0.535518" mass="3.5879" diaginertia="0.0349596 0.0281483 0.0106201" />
            <joint name="panda_joint4" pos="0 0 0" axis="0 0 1" range="-3.0718 -0.0698" actuatorfrcrange="-87 87" damping="4" armature="0" />
            <geom type="mesh" mesh="link4_0" material="white" contype="0" conaffinity="0" />
            <geom type="mesh" mesh="link4_1" material="white" contype="0" conaffinity="0" />
            <geom type="mesh" mesh="link4_2" material="black" contype="0" conaffinity="0" />
            <geom type="mesh" mesh="link4_3" material="white" contype="0" conaffinity="0" />
            <geom type="mesh" mesh="link4_c" rgba="1 1 1 0" group="1" />
            <body name="panda_link5" pos="-0.0825 0.384 0" quat="0.707107 -0.707107 0 0">
              <inertial pos="-0.011953 0.041065 -0.038437" quat="0.987313 -0.0121954 0.0719187 -0.141037" mass="1.22595" diaginertia="0.0367625 0.0288531 0.00803437" />
              <joint name="panda_joint5" pos="0 0 0" axis="0 0 1" range="-2.8973 2.8973" actuatorfrcrange="-12 12" damping="4" armature="0" />
              <geom type="mesh" mesh="link5_0" material="black" contype="0" conaffinity="0" />
              <geom type="mesh" mesh="link5_1" material="white" contype="0" conaffinity="0" />
              <geom type="mesh" mesh="link5_2" material="white" contype="0" conaffinity="0" />
              <geom type="mesh" mesh="link5_c0" rgba="1 1 1 0" group="1" />
              <geom type="mesh" mesh="link5_c1" rgba="1 1 1 0" group="1" />
              <geom type="mesh" mesh="link5_c2" rgba="1 1 1 0" group="1" />
              <body name="panda_link6" quat="0.707107 0.707107 0 0">
                <inertial pos="0.060149 -0.014117 -0.010517" quat="0.101075 0.59332 0.0287227 0.798079" mass="1.66656" diaginertia="0.00584276 0.00431037 0.00159787" />
                <joint name="panda_joint6" pos="0 0 0" axis="0 0 1" range="-0.0175 3.7525" actuatorfrcrange="-12 12" damping="4" armature="0" />
                <geom type="mesh" mesh="link6_0" material="off_white" contype="0" conaffinity="0" />
                <geom type="mesh" mesh="link6_1" material="white" contype="0" conaffinity="0" />
                <geom type="mesh" mesh="link6_2" material="black" contype="0" conaffinity="0" />
                <geom type="mesh" mesh="link6_3" material="white" contype="0" conaffinity="0" />
                <geom type="mesh" mesh="link6_4" material="white" contype="0" conaffinity="0" />
                <geom type="mesh" mesh="link6_5" material="white" contype="0" conaffinity="0" />
                <geom type="mesh" mesh="link6_6" material="white" contype="0" conaffinity="0" />
                <geom type="mesh" mesh="link6_7" material="light_blue" contype="0" conaffinity="0" />
                <geom type="mesh" mesh="link6_8" material="light_blue" contype="0" conaffinity="0" />
                <geom type="mesh" mesh="link6_9" material="black" contype="0" conaffinity="0" />
                <geom type="mesh" mesh="link6_10" material="black" contype="0" conaffinity="0" />
                <geom type="mesh" mesh="link6_11" material="white" contype="0" conaffinity="0" />
                <geom type="mesh" mesh="link6_12" material="green" contype="0" conaffinity="0" />
                <geom type="mesh" mesh="link6_13" material="white" contype="0" conaffinity="0" />
                <geom type="mesh" mesh="link6_14" material="black" contype="0" conaffinity="0" />
                <geom type="mesh" mesh="link6_15" material="black" contype="0" conaffinity="0" />
                <geom type="mesh" mesh="link6_16" material="white" contype="0" conaffinity="0" />
                <geom type="mesh" mesh="link6_c" rgba="1 1 1 0" group="1" />
                <body name="panda_link7" pos="0.088 0 0" quat="0.707107 0.707107 0 0">
                  <inertial pos="0.0535956 -0.00213401 0.045858" quat="0.594329 -0.0303333 0.0970674 0.797766" mass="1.46552" diaginertia="0.0155969 0.0137507 0.00943568" />
                  <joint name="panda_joint7" pos="0 0 0" axis="0 0 1" range="-2.8973 2.8973" actuatorfrcrange="-12 12" damping="4" armature="0" />
                  <geom type="mesh" mesh="link7_0" material="white" contype="0" conaffinity="0" />
                  <geom type="mesh" mesh="link7_1" material="black" contype="0" conaffinity="0" />
                  <geom type="mesh" mesh="link7_2" material="black" contype="0" conaffinity="0" />
                  <geom type="mesh" mesh="link7_3" material="black" contype="0" conaffinity="0" />
                  <geom type="mesh" mesh="link7_4" material="black" contype="0" conaffinity="0" />
                  <geom type="mesh" mesh="link7_5" material="black" contype="0" conaffinity="0" />
                  <geom type="mesh" mesh="link7_6" material="black" contype="0" conaffinity="0" />
                  <geom type="mesh" mesh="link7_7" material="white" contype="0" conaffinity="0" />
                  <geom type="mesh" mesh="link7_c" rgba="1 1 1 0" group="1" />
                  <geom pos="0 0 0.107" quat="0.92388 0 0 -0.382683" type="mesh" mesh="hand_0" material="off_white" contype="0" conaffinity="0" />
                  <geom pos="0 0 0.107" quat="0.92388 0 0 -0.382683" type="mesh" mesh="hand_1" material="black" contype="0" conaffinity="0" />
                  <geom pos="0 0 0.107" quat="0.92388 0 0 -0.382683" type="mesh" mesh="hand_2" material="black" contype="0" conaffinity="0" />
                  <geom pos="0 0 0.107" quat="0.92388 0 0 -0.382683" type="mesh" mesh="hand_3" material="white" contype="0" conaffinity="0" />
                  <geom pos="0 0 0.107" quat="0.92388 0 0 -0.382683" type="mesh" mesh="hand_4" material="off_white" contype="0" conaffinity="0" />
                  <geom pos="0 0 0.107" quat="0.92388 0 0 -0.382683" type="mesh" mesh="hand_c" rgba="1 1 1 0" group="1" />
                  <body name="panda_leftfinger" pos="0 0 0.1654" quat="0.92388 0 0 -0.382683">
                    <inertial pos="0 0 0" mass="0.015" diaginertia="2.375e-06 2.375e-06 7.5e-07" />
                    <joint name="panda_finger_joint1" pos="0 0 0" axis="0 1 0" type="slide" range="0 0.04" actuatorfrcrange="-100 100" damping="50" armature="0" />
                    <geom type="mesh" mesh="finger_0" material="off_white" contype="0" conaffinity="0" />
                    <geom type="mesh" mesh="finger_1" material="black" contype="0" conaffinity="0" />
                    <geom type="box" pos="0 0.0144 0.018" size="0.0105 0.0119 0.018" rgba="1 1 1 1" group="1" />
                    <geom type="box" pos="0 0.0144 0.0448" size="0.0105 0.0119 0.0089" rgba="1 1 1 1" group="1" />
                    <geom type="box" pos="0 0.0054 0.045" size="0.00895 0.00555 0.00895" rgba="1 1 1 1" group="1" />
                    <!-- <geom size="0.011 0.0075 0.01" pos="0 0.0185 0.011" type="box" rgba="1 1 1 0" />
                    <geom size="0.011 0.0044 0.0019" pos="0 0.0068 0.0022" type="box" rgba="1 1 1 0" />
                    <geom size="0.00875 0.0035 0.01175" pos="0 0.0159 0.02835" quat="0.965926 0.258819 0 0" type="box" rgba="1 1 1 0" />
                    <geom size="0.00875 0.0076 0.00925" pos="0 0.00758 0.04525" type="box" rgba="1 1 1 0" /> -->
                  </body>
                  <body name="panda_rightfinger" pos="0 0 0.1654" quat="0.382683 0 0 0.92388">
                    <inertial pos="0 0 0" mass="0.015" diaginertia="2.375e-06 2.375e-06 7.5e-07" />
                    <joint name="panda_finger_joint2" pos="0 0 0" axis="0 1 0" type="slide" range="0 0.04" actuatorfrcrange="-100 100" damping="50" armature="0" />
                    <geom type="mesh" mesh="finger_0" material="off_white" contype="0" conaffinity="0" />
                    <geom type="mesh" mesh="finger_1" material="black" contype="0" conaffinity="0" />
                    <geom type="box" pos="0 0.0144 0.018" size="0.0105 0.0119 0.018" rgba="1 1 1 1" group="1" />
                    <geom type="box" pos="0 0.0144 0.0448" size="0.0105 0.0119 0.0089" rgba="1 1 1 1" group="1" />
                    <geom type="box" pos="0 0.0054 0.045" size="0.00895 0.00555 0.00895" rgba="1 1 1 1" group="1" />
                    <!-- <geom size="0.011 0.0075 0.01" pos="0 0.0185 0.011" type="box" rgba="1 1 1 0" />
                    <geom size="0.011 0.0044 0.0019" pos="0 0.0068 0.0022" type="box" rgba="1 1 1 0" />
                    <geom size="0.00875 0.0035 0.01175" pos="0 0.0159 0.02835" quat="0.965926 0.258819 0 0" type="box" rgba="1 1 1 0" />
                    <geom size="0.00875 0.0076 0.00925" pos="0 0.00758 0.04525" type="box" rgba="1 1 1 0" /> -->
                  </body>
                </body>
              </body>
            </body>
          </body>
        </body>
      </body>
    </body>
    <light name="sun" mode="fixed" pos="1.0 -1.0 2.0" dir="-0.3 0.2 -1.0" />
    <camera name="overview" pos="1.0 -1.0 0.8" xyaxes="1 0 0 0 0 1" />
    <geom name="ground" type="box" pos="0 0 -1.06" size="2 2 0.01" rgba="0.2 0.2 0.2 1" friction="1 0.01 0.001" contype="1" conaffinity="1" />
    <geom name="table_top" type="box" pos="0.5 0 -0.025" size="0.55 0.45 0.025" rgba="0.38 0.3 0.18 1" friction="1 0.01 0.001" contype="1" conaffinity="1" />
    <geom name="table_leg_front_left" type="box" pos="0.03 0.37 -0.55" size="0.03 0.03 0.5" rgba="0.25 0.25 0.25 1" friction="1 0.01 0.001" contype="1" conaffinity="1" />
    <geom name="table_leg_front_right" type="box" pos="0.03 -0.37 -0.55" size="0.03 0.03 0.5" rgba="0.25 0.25 0.25 1" friction="1 0.01 0.001" contype="1" conaffinity="1" />
    <geom name="table_leg_back_left" type="box" pos="0.97 0.37 -0.55" size="0.03 0.03 0.5" rgba="0.25 0.25 0.25 1" friction="1 0.01 0.001" contype="1" conaffinity="1" />
    <geom name="table_leg_back_right" type="box" pos="0.97 -0.37 -0.55" size="0.03 0.03 0.5" rgba="0.25 0.25 0.25 1" friction="1 0.01 0.001" contype="1" conaffinity="1" />
    <body name="pick_cube" pos="0.45 0 0.025">
      <freejoint name="pick_cube_freejoint" />
      <geom name="pick_cube_geom" type="box" size="0.025 0.025 0.025" mass="5.0" rgba="0.0 1.0 0.0 1.0" friction="1 0.01 0.001" contype="1" conaffinity="1" group="1"/>
    </body>
    <geom name="target_box_floor" type="box" pos="0.58 -0.36 0.005" size="0.07 0.07 0.005" rgba="0.72 0.7 0.62 1" friction="1 0.01 0.001" contype="1" conaffinity="1" />
    <geom name="target_box_left_wall" type="box" pos="0.515 -0.36 0.04" size="0.005 0.07 0.03" rgba="0.55 0.43 0.28 1" friction="1 0.01 0.001" contype="1" conaffinity="1" />
    <geom name="target_box_right_wall" type="box" pos="0.645 -0.36 0.04" size="0.005 0.07 0.03" rgba="0.55 0.43 0.28 1" friction="1 0.01 0.001" contype="1" conaffinity="1" />
    <geom name="target_box_front_wall" type="box" pos="0.58 -0.295 0.04" size="0.07 0.005 0.03" rgba="0.55 0.43 0.28 1" friction="1 0.01 0.001" contype="1" conaffinity="1" />
    <geom name="target_box_back_wall" type="box" pos="0.58 -0.425 0.04" size="0.07 0.005 0.03" rgba="0.55 0.43 0.28 1" friction="1 0.01 0.001" contype="1" conaffinity="1" />
    <site name="waypoint_marker" type="sphere" pos="0.5 0 0.3" size="0.012" rgba="0.2 0.6 1.0 0.4" />
    <site name="goal_marker" type="sphere" pos="0.58 -0.36 0.115" size="0.012" rgba="1.0 0.4 0.2 0.4" />
  </worldbody>
  <contact>
    <exclude body1="panda_link1" body2="panda_link2" />
    <exclude body1="panda_link1" body2="panda_link3" />
    <exclude body1="panda_link1" body2="panda_link4" />
    <exclude body1="panda_link1" body2="panda_link5" />
    <exclude body1="panda_link1" body2="panda_link6" />
    <exclude body1="panda_link1" body2="panda_link7" />
    <exclude body1="panda_link1" body2="panda_leftfinger" />
    <exclude body1="panda_link1" body2="panda_rightfinger" />
    <exclude body1="panda_link2" body2="panda_link3" />
    <exclude body1="panda_link2" body2="panda_link4" />
    <exclude body1="panda_link2" body2="panda_link5" />
    <exclude body1="panda_link2" body2="panda_link6" />
    <exclude body1="panda_link2" body2="panda_link7" />
    <exclude body1="panda_link2" body2="panda_leftfinger" />
    <exclude body1="panda_link2" body2="panda_rightfinger" />
    <exclude body1="panda_link3" body2="panda_link4" />
    <exclude body1="panda_link3" body2="panda_link5" />
    <exclude body1="panda_link3" body2="panda_link6" />
    <exclude body1="panda_link3" body2="panda_link7" />
    <exclude body1="panda_link3" body2="panda_leftfinger" />
    <exclude body1="panda_link3" body2="panda_rightfinger" />
    <exclude body1="panda_link4" body2="panda_link5" />
    <exclude body1="panda_link4" body2="panda_link6" />
    <exclude body1="panda_link4" body2="panda_link7" />
    <exclude body1="panda_link4" body2="panda_leftfinger" />
    <exclude body1="panda_link4" body2="panda_rightfinger" />
    <exclude body1="panda_link5" body2="panda_link6" />
    <exclude body1="panda_link5" body2="panda_link7" />
    <exclude body1="panda_link5" body2="panda_leftfinger" />
    <exclude body1="panda_link5" body2="panda_rightfinger" />
    <exclude body1="panda_link6" body2="panda_link7" />
    <exclude body1="panda_link6" body2="panda_leftfinger" />
    <exclude body1="panda_link6" body2="panda_rightfinger" />
    <exclude body1="panda_link7" body2="panda_leftfinger" />
    <exclude body1="panda_link7" body2="panda_rightfinger" />
    <exclude body1="panda_leftfinger" body2="panda_rightfinger" />
  </contact>
  <option timestep="0.01" gravity="0 0 -9.81" integrator="implicitfast" iterations="50" />
  <visual>
    <map znear="0.01" zfar="10" />
  </visual>
  <actuator>
    <position name="panda_joint1" joint="panda_joint1" kp="80" ctrllimited="true" ctrlrange="-2.8973 2.8973" forcelimited="true" forcerange="-87 87" />
    <position name="panda_joint2" joint="panda_joint2" kp="80" ctrllimited="true" ctrlrange="-1.7628 1.7628" forcelimited="true" forcerange="-87 87" />
    <position name="panda_joint3" joint="panda_joint3" kp="80" ctrllimited="true" ctrlrange="-2.8973 2.8973" forcelimited="true" forcerange="-87 87" />
    <position name="panda_joint4" joint="panda_joint4" kp="80" ctrllimited="true" ctrlrange="-3.0718 -0.0698" forcelimited="true" forcerange="-87 87" />
    <position name="panda_joint5" joint="panda_joint5" kp="80" ctrllimited="true" ctrlrange="-2.8973 2.8973" forcelimited="true" forcerange="-12 12" />
    <position name="panda_joint6" joint="panda_joint6" kp="80" ctrllimited="true" ctrlrange="-0.0175 3.7525" forcelimited="true" forcerange="-12 12" />
    <position name="panda_joint7" joint="panda_joint7" kp="80" ctrllimited="true" ctrlrange="-2.8973 2.8973" forcelimited="true" forcerange="-12 12" />
    <position name="panda_finger_joint1" joint="panda_finger_joint1" kp="1000" ctrllimited="true" ctrlrange="0 0.04" forcelimited="true" forcerange="-200 200" />
    <position name="panda_finger_joint2" joint="panda_finger_joint2" kp="1000" ctrllimited="true" ctrlrange="0 0.04" forcelimited="true" forcerange="-200 200" />
  </actuator>
</mujoco>
