<?xml version='1.0' encoding='utf-8'?>
<mujoco model="franka_pick_place">
  <compiler angle="radian" meshdir="assets/" />
  <option integrator="implicitfast" timestep="0.01" gravity="0 0 -9.81" iterations="50" />
  <size nkey="1" />
  <default>
    <default class="panda">
      <material shininess="0.25" />
      <joint range="-2.8973 2.8973" armature="0.1" damping="1" />
      <general ctrlrange="-2.8973 2.8973" forcerange="-87 87" biastype="affine" />
      <default class="finger">
        <joint type="slide" range="0 0.04" />
      </default>
      <default class="visual">
        <geom type="mesh" contype="0" conaffinity="0" group="2" />
      </default>
      <default class="collision">
        <geom type="mesh" group="3" />
        <default class="fingertip_pad_collision_1">
          <geom size="0.0085 0.004 0.0085" type="box" />
        </default>
        <default class="fingertip_pad_collision_2">
          <geom size="0.003 0.002 0.003" type="box" />
        </default>
        <default class="fingertip_pad_collision_3">
          <geom size="0.003 0.002 0.003" type="box" />
        </default>
        <default class="fingertip_pad_collision_4">
          <geom size="0.003 0.002 0.0035" type="box" />
        </default>
        <default class="fingertip_pad_collision_5">
          <geom size="0.003 0.002 0.0035" type="box" />
        </default>
      </default>
    </default>
  </default>
  <asset>
    <material name="white" class="panda" />
    <material name="off_white" class="panda" rgba="0.901961 0.921569 0.929412 1" />
    <material name="black" class="panda" rgba="0.25 0.25 0.25 1" />
    <material name="green" class="panda" rgba="0 1 0 1" />
    <material name="light_blue" class="panda" rgba="0.039216 0.541176 0.780392 1" />
    <mesh name="link0_c" content_type="model/stl" file="../../../../../Downloads/franka_emika_panda/assets/link0.stl" />
    <mesh name="link1_c" content_type="model/stl" file="../../../../../Downloads/franka_emika_panda/assets/link1.stl" />
    <mesh name="link2_c" content_type="model/stl" file="../../../../../Downloads/franka_emika_panda/assets/link2.stl" />
    <mesh name="link3_c" content_type="model/stl" file="../../../../../Downloads/franka_emika_panda/assets/link3.stl" />
    <mesh name="link4_c" content_type="model/stl" file="../../../../../Downloads/franka_emika_panda/assets/link4.stl" />
    <mesh name="link5_c0" content_type="model/obj" file="../../../../../Downloads/franka_emika_panda/assets/link5_collision_0.obj" />
    <mesh name="link5_c1" content_type="model/obj" file="../../../../../Downloads/franka_emika_panda/assets/link5_collision_1.obj" />
    <mesh name="link5_c2" content_type="model/obj" file="../../../../../Downloads/franka_emika_panda/assets/link5_collision_2.obj" />
    <mesh name="link6_c" content_type="model/stl" file="../../../../../Downloads/franka_emika_panda/assets/link6.stl" />
    <mesh name="link7_c" content_type="model/stl" file="../../../../../Downloads/franka_emika_panda/assets/link7.stl" />
    <mesh name="hand_c" content_type="model/stl" file="../../../../../Downloads/franka_emika_panda/assets/hand.stl" />
    <mesh name="link0_0" content_type="model/obj" file="../../../../../Downloads/franka_emika_panda/assets/link0_0.obj" />
    <mesh name="link0_1" content_type="model/obj" file="../../../../../Downloads/franka_emika_panda/assets/link0_1.obj" />
    <mesh name="link0_2" content_type="model/obj" file="../../../../../Downloads/franka_emika_panda/assets/link0_2.obj" />
    <mesh name="link0_3" content_type="model/obj" file="../../../../../Downloads/franka_emika_panda/assets/link0_3.obj" />
    <mesh name="link0_4" content_type="model/obj" file="../../../../../Downloads/franka_emika_panda/assets/link0_4.obj" />
    <mesh name="link0_5" content_type="model/obj" file="../../../../../Downloads/franka_emika_panda/assets/link0_5.obj" />
    <mesh name="link0_7" content_type="model/obj" file="../../../../../Downloads/franka_emika_panda/assets/link0_7.obj" />
    <mesh name="link0_8" content_type="model/obj" file="../../../../../Downloads/franka_emika_panda/assets/link0_8.obj" />
    <mesh name="link0_9" content_type="model/obj" file="../../../../../Downloads/franka_emika_panda/assets/link0_9.obj" />
    <mesh name="link0_10" content_type="model/obj" file="../../../../../Downloads/franka_emika_panda/assets/link0_10.obj" />
    <mesh name="link0_11" content_type="model/obj" file="../../../../../Downloads/franka_emika_panda/assets/link0_11.obj" />
    <mesh name="link1" content_type="model/obj" file="../../../../../Downloads/franka_emika_panda/assets/link1.obj" />
    <mesh name="link2" content_type="model/obj" file="../../../../../Downloads/franka_emika_panda/assets/link2.obj" />
    <mesh name="link3_0" content_type="model/obj" file="../../../../../Downloads/franka_emika_panda/assets/link3_0.obj" />
    <mesh name="link3_1" content_type="model/obj" file="../../../../../Downloads/franka_emika_panda/assets/link3_1.obj" />
    <mesh name="link3_2" content_type="model/obj" file="../../../../../Downloads/franka_emika_panda/assets/link3_2.obj" />
    <mesh name="link3_3" content_type="model/obj" file="../../../../../Downloads/franka_emika_panda/assets/link3_3.obj" />
    <mesh name="link4_0" content_type="model/obj" file="../../../../../Downloads/franka_emika_panda/assets/link4_0.obj" />
    <mesh name="link4_1" content_type="model/obj" file="../../../../../Downloads/franka_emika_panda/assets/link4_1.obj" />
    <mesh name="link4_2" content_type="model/obj" file="../../../../../Downloads/franka_emika_panda/assets/link4_2.obj" />
    <mesh name="link4_3" content_type="model/obj" file="../../../../../Downloads/franka_emika_panda/assets/link4_3.obj" />
    <mesh name="link5_0" content_type="model/obj" file="../../../../../Downloads/franka_emika_panda/assets/link5_0.obj" />
    <mesh name="link5_1" content_type="model/obj" file="../../../../../Downloads/franka_emika_panda/assets/link5_1.obj" />
    <mesh name="link5_2" content_type="model/obj" file="../../../../../Downloads/franka_emika_panda/assets/link5_2.obj" />
    <mesh name="link6_0" content_type="model/obj" file="../../../../../Downloads/franka_emika_panda/assets/link6_0.obj" />
    <mesh name="link6_1" content_type="model/obj" file="../../../../../Downloads/franka_emika_panda/assets/link6_1.obj" />
    <mesh name="link6_2" content_type="model/obj" file="../../../../../Downloads/franka_emika_panda/assets/link6_2.obj" />
    <mesh name="link6_3" content_type="model/obj" file="../../../../../Downloads/franka_emika_panda/assets/link6_3.obj" />
    <mesh name="link6_4" content_type="model/obj" file="../../../../../Downloads/franka_emika_panda/assets/link6_4.obj" />
    <mesh name="link6_5" content_type="model/obj" file="../../../../../Downloads/franka_emika_panda/assets/link6_5.obj" />
    <mesh name="link6_6" content_type="model/obj" file="../../../../../Downloads/franka_emika_panda/assets/link6_6.obj" />
    <mesh name="link6_7" content_type="model/obj" file="../../../../../Downloads/franka_emika_panda/assets/link6_7.obj" />
    <mesh name="link6_8" content_type="model/obj" file="../../../../../Downloads/franka_emika_panda/assets/link6_8.obj" />
    <mesh name="link6_9" content_type="model/obj" file="../../../../../Downloads/franka_emika_panda/assets/link6_9.obj" />
    <mesh name="link6_10" content_type="model/obj" file="../../../../../Downloads/franka_emika_panda/assets/link6_10.obj" />
    <mesh name="link6_11" content_type="model/obj" file="../../../../../Downloads/franka_emika_panda/assets/link6_11.obj" />
    <mesh name="link6_12" content_type="model/obj" file="../../../../../Downloads/franka_emika_panda/assets/link6_12.obj" />
    <mesh name="link6_13" content_type="model/obj" file="../../../../../Downloads/franka_emika_panda/assets/link6_13.obj" />
    <mesh name="link6_14" content_type="model/obj" file="../../../../../Downloads/franka_emika_panda/assets/link6_14.obj" />
    <mesh name="link6_15" content_type="model/obj" file="../../../../../Downloads/franka_emika_panda/assets/link6_15.obj" />
    <mesh name="link6_16" content_type="model/obj" file="../../../../../Downloads/franka_emika_panda/assets/link6_16.obj" />
    <mesh name="link7_0" content_type="model/obj" file="../../../../../Downloads/franka_emika_panda/assets/link7_0.obj" />
    <mesh name="link7_1" content_type="model/obj" file="../../../../../Downloads/franka_emika_panda/assets/link7_1.obj" />
    <mesh name="link7_2" content_type="model/obj" file="../../../../../Downloads/franka_emika_panda/assets/link7_2.obj" />
    <mesh name="link7_3" content_type="model/obj" file="../../../../../Downloads/franka_emika_panda/assets/link7_3.obj" />
    <mesh name="link7_4" content_type="model/obj" file="../../../../../Downloads/franka_emika_panda/assets/link7_4.obj" />
    <mesh name="link7_5" content_type="model/obj" file="../../../../../Downloads/franka_emika_panda/assets/link7_5.obj" />
    <mesh name="link7_6" content_type="model/obj" file="../../../../../Downloads/franka_emika_panda/assets/link7_6.obj" />
    <mesh name="link7_7" content_type="model/obj" file="../../../../../Downloads/franka_emika_panda/assets/link7_7.obj" />
    <mesh name="hand_0" content_type="model/obj" file="../../../../../Downloads/franka_emika_panda/assets/hand_0.obj" />
    <mesh name="hand_1" content_type="model/obj" file="../../../../../Downloads/franka_emika_panda/assets/hand_1.obj" />
    <mesh name="hand_2" content_type="model/obj" file="../../../../../Downloads/franka_emika_panda/assets/hand_2.obj" />
    <mesh name="hand_3" content_type="model/obj" file="../../../../../Downloads/franka_emika_panda/assets/hand_3.obj" />
    <mesh name="hand_4" content_type="model/obj" file="../../../../../Downloads/franka_emika_panda/assets/hand_4.obj" />
    <mesh name="finger_0" content_type="model/obj" file="../../../../../Downloads/franka_emika_panda/assets/finger_0.obj" />
    <mesh name="finger_1" content_type="model/obj" file="../../../../../Downloads/franka_emika_panda/assets/finger_1.obj" />
    <material name="table_mat" rgba="0.38 0.30 0.18 1" />
    <material name="cube_mat" rgba="0.0 1.0 0.0 1" />
    <material name="target_floor_mat" rgba="0.72 0.70 0.62 1" />
    <material name="target_wall_mat" rgba="0.55 0.43 0.28 1" />
  </asset>
  <worldbody>
    <light name="top" pos="0 0 2" dir="0 0 -1" mode="trackcom" />
    <body name="link0" childclass="panda">
      <inertial pos="-0.041018 -0.00014 0.049974" quat="0.00630474 0.751245 0.00741774 0.659952" mass="0.629769" diaginertia="0.00430465 0.00387984 0.00313051" />
      <geom class="visual" material="off_white" mesh="link0_0" />
      <geom class="visual" material="black" mesh="link0_1" />
      <geom class="visual" material="off_white" mesh="link0_2" />
      <geom class="visual" material="black" mesh="link0_3" />
      <geom class="visual" material="off_white" mesh="link0_4" />
      <geom class="visual" material="black" mesh="link0_5" />
      <geom class="visual" material="white" mesh="link0_7" />
      <geom class="visual" material="white" mesh="link0_8" />
      <geom class="visual" material="black" mesh="link0_9" />
      <geom class="visual" material="off_white" mesh="link0_10" />
      <geom class="visual" material="white" mesh="link0_11" />
      <geom class="collision" mesh="link0_c" />
      <body name="link1" pos="0 0 0.333">
        <inertial pos="0.003875 0.002081 -0.04762" quat="0.711549 0.00634377 -0.0131124 0.702485" mass="4.97068" diaginertia="0.707137 0.703435 0.00852456" />
        <joint name="joint1" pos="0 0 0" axis="0 0 1" />
        <geom class="visual" material="white" mesh="link1" />
        <geom class="collision" mesh="link1_c" />
        <body name="link2" quat="0.707107 -0.707107 0 0">
          <inertial pos="-0.003141 -0.02872 0.003495" quat="-0.168175 0.828366 -0.122878 0.520027" mass="0.646926" diaginertia="0.0310326 0.0283001 0.00273425" />
          <joint name="joint2" pos="0 0 0" axis="0 0 1" range="-1.7628 1.7628" />
          <geom class="visual" material="white" mesh="link2" />
          <geom class="collision" mesh="link2_c" />
          <body name="link3" pos="0 -0.316 0" quat="0.707107 0.707107 0 0">
            <inertial pos="0.027518 0.039252 -0.066502" quat="0.662769 -0.00678331 0.252053 0.705096" mass="3.2286" diaginertia="0.0415014 0.0414793 0.00124635" />
            <joint name="joint3" pos="0 0 0" axis="0 0 1" />
            <geom class="visual" material="white" mesh="link3_0" />
            <geom class="visual" material="white" mesh="link3_1" />
            <geom class="visual" material="white" mesh="link3_2" />
            <geom class="visual" material="black" mesh="link3_3" />
            <geom class="collision" mesh="link3_c" />
            <body name="link4" pos="0.0825 0 0" quat="0.707107 0.707107 0 0">
              <inertial pos="-0.05317 0.104419 0.027454" quat="0.65058 0.529822 -0.0962034 0.535518" mass="3.5879" diaginertia="0.0349596 0.0281483 0.0106201" />
              <joint name="joint4" pos="0 0 0" axis="0 0 1" range="-3.0718 -0.0698" />
              <geom class="visual" material="white" mesh="link4_0" />
              <geom class="visual" material="white" mesh="link4_1" />
              <geom class="visual" material="black" mesh="link4_2" />
              <geom class="visual" material="white" mesh="link4_3" />
              <geom class="collision" mesh="link4_c" />
              <body name="link5" pos="-0.0825 0.384 0" quat="0.707107 -0.707107 0 0">
                <inertial pos="-0.011953 0.041065 -0.038437" quat="0.987313 -0.0121954 0.0719187 -0.141037" mass="1.22595" diaginertia="0.0367625 0.0288531 0.00803437" />
                <joint name="joint5" pos="0 0 0" axis="0 0 1" />
                <geom class="visual" material="black" mesh="link5_0" />
                <geom class="visual" material="white" mesh="link5_1" />
                <geom class="visual" material="white" mesh="link5_2" />
                <geom class="collision" mesh="link5_c0" />
                <geom class="collision" mesh="link5_c1" />
                <geom class="collision" mesh="link5_c2" />
                <body name="link6" quat="0.707107 0.707107 0 0">
                  <inertial pos="0.060149 -0.014117 -0.010517" quat="0.101075 0.59332 0.0287227 0.798079" mass="1.66656" diaginertia="0.00584276 0.00431037 0.00159787" />
                  <joint name="joint6" pos="0 0 0" axis="0 0 1" range="-0.0175 3.7525" />
                  <geom class="visual" material="off_white" mesh="link6_0" />
                  <geom class="visual" material="white" mesh="link6_1" />
                  <geom class="visual" material="black" mesh="link6_2" />
                  <geom class="visual" material="white" mesh="link6_3" />
                  <geom class="visual" material="white" mesh="link6_4" />
                  <geom class="visual" material="white" mesh="link6_5" />
                  <geom class="visual" material="white" mesh="link6_6" />
                  <geom class="visual" material="light_blue" mesh="link6_7" />
                  <geom class="visual" material="light_blue" mesh="link6_8" />
                  <geom class="visual" material="black" mesh="link6_9" />
                  <geom class="visual" material="black" mesh="link6_10" />
                  <geom class="visual" material="white" mesh="link6_11" />
                  <geom class="visual" material="green" mesh="link6_12" />
                  <geom class="visual" material="white" mesh="link6_13" />
                  <geom class="visual" material="black" mesh="link6_14" />
                  <geom class="visual" material="black" mesh="link6_15" />
                  <geom class="visual" material="white" mesh="link6_16" />
                  <geom class="collision" mesh="link6_c" />
                  <body name="link7" pos="0.088 0 0" quat="0.707107 0.707107 0 0">
                    <inertial pos="0.010517 -0.004252 0.061597" quat="0.992939 -0.0762041 0.0733595 -0.0537067" mass="0.735522" diaginertia="0.0127345 0.0101055 0.00451803" />
                    <joint name="joint7" pos="0 0 0" axis="0 0 1" />
                    <geom class="visual" material="white" mesh="link7_0" />
                    <geom class="visual" material="black" mesh="link7_1" />
                    <geom class="visual" material="black" mesh="link7_2" />
                    <geom class="visual" material="black" mesh="link7_3" />
                    <geom class="visual" material="black" mesh="link7_4" />
                    <geom class="visual" material="black" mesh="link7_5" />
                    <geom class="visual" material="black" mesh="link7_6" />
                    <geom class="visual" material="white" mesh="link7_7" />
                    <geom class="collision" mesh="link7_c" />
                    <body name="hand" pos="0 0 0.107" quat="0.92388 0 0 -0.382683">
                      <inertial pos="-0.01 0 0.03" mass="0.73" diaginertia="0.001 0.0025 0.0017" />
                      <geom class="visual" material="off_white" mesh="hand_0" />
                      <geom class="visual" material="black" mesh="hand_1" />
                      <geom class="visual" material="black" mesh="hand_2" />
                      <geom class="visual" material="white" mesh="hand_3" />
                      <geom class="visual" material="off_white" mesh="hand_4" />
                      <geom class="collision" mesh="hand_c" />
                      <body name="left_finger" pos="0 0 0.0584">
                        <inertial pos="0 0 0" mass="0.015" diaginertia="2.375e-06 2.375e-06 7.5e-07" />
                        <joint name="finger_joint1" class="finger" pos="0 0 0" axis="0 1 0" />
                        <geom class="visual" material="off_white" mesh="finger_0" />
                        <geom class="visual" material="black" mesh="finger_1" />
                        <geom class="collision" mesh="finger_0" />
                        <geom class="fingertip_pad_collision_1" pos="0 0.0055 0.0445" />
                        <geom class="fingertip_pad_collision_2" pos="0.0055 0.002 0.05" />
                        <geom class="fingertip_pad_collision_3" pos="-0.0055 0.002 0.05" />
                        <geom class="fingertip_pad_collision_4" pos="0.0055 0.002 0.0395" />
                        <geom class="fingertip_pad_collision_5" pos="-0.0055 0.002 0.0395" />
                      </body>
                      <body name="right_finger" pos="0 0 0.0584" quat="0 0 0 1">
                        <inertial pos="0 0 0" mass="0.015" diaginertia="2.375e-06 2.375e-06 7.5e-07" />
                        <joint name="finger_joint2" class="finger" pos="0 0 0" axis="0 1 0" />
                        <geom class="visual" material="off_white" mesh="finger_0" />
                        <geom class="visual" material="black" mesh="finger_1" />
                        <geom class="collision" mesh="finger_0" />
                        <geom class="fingertip_pad_collision_1" pos="0 0.0055 0.0445" />
                        <geom class="fingertip_pad_collision_2" pos="0.0055 0.002 0.05" />
                        <geom class="fingertip_pad_collision_3" pos="-0.0055 0.002 0.05" />
                        <geom class="fingertip_pad_collision_4" pos="0.0055 0.002 0.0395" />
                        <geom class="fingertip_pad_collision_5" pos="-0.0055 0.002 0.0395" />
                      </body>
                    </body>
                  </body>
                </body>
              </body>
            </body>
          </body>
        </body>
      </body>
    </body>
    <light name="sun" mode="fixed" pos="1.0 -1.0 2.0" dir="-0.3 0.2 -1.0" />
    <camera name="overview" pos="1.0 -1.0 0.8" xyaxes="1 0 0 0 0 1" />
    <geom name="ground" type="box" pos="0 0 -1.06" size="2 2 0.01" rgba="0.2 0.2 0.2 1" friction="1 0.01 0.001" contype="1" conaffinity="1" />
    <geom name="table_top" type="box" pos="0.5 0 -0.025" size="0.55 0.45 0.025" rgba="0.38 0.3 0.18 1" friction="1 0.01 0.001" contype="1" conaffinity="1" />
    <geom name="table_leg_front_left" type="box" pos="0.03 0.37 -0.55" size="0.03 0.03 0.5" rgba="0.25 0.25 0.25 1" friction="1 0.01 0.001" contype="1" conaffinity="1" />
    <geom name="table_leg_front_right" type="box" pos="0.03 -0.37 -0.55" size="0.03 0.03 0.5" rgba="0.25 0.25 0.25 1" friction="1 0.01 0.001" contype="1" conaffinity="1" />
    <geom name="table_leg_back_left" type="box" pos="0.97 0.37 -0.55" size="0.03 0.03 0.5" rgba="0.25 0.25 0.25 1" friction="1 0.01 0.001" contype="1" conaffinity="1" />
    <geom name="table_leg_back_right" type="box" pos="0.97 -0.37 -0.55" size="0.03 0.03 0.5" rgba="0.25 0.25 0.25 1" friction="1 0.01 0.001" contype="1" conaffinity="1" />
    <body name="pick_cube" pos="0.45 0 0.025">
      <freejoint name="pick_cube_freejoint" />
      <geom name="pick_cube_geom" type="box" size="0.025 0.025 0.025" rgba="0.0 1.0 0.0 1.0" friction="1 0.01 0.001" contype="1" conaffinity="1" />
    </body>
    <geom name="target_box_floor" type="box" pos="0.58 -0.36 0.005" size="0.07 0.07 0.005" rgba="0.72 0.7 0.62 1" friction="1 0.01 0.001" contype="1" conaffinity="1" />
    <geom name="target_box_left_wall" type="box" pos="0.515 -0.36 0.04" size="0.005 0.07 0.03" rgba="0.55 0.43 0.28 1" friction="1 0.01 0.001" contype="1" conaffinity="1" />
    <geom name="target_box_right_wall" type="box" pos="0.645 -0.36 0.04" size="0.005 0.07 0.03" rgba="0.55 0.43 0.28 1" friction="1 0.01 0.001" contype="1" conaffinity="1" />
    <geom name="target_box_front_wall" type="box" pos="0.58 -0.295 0.04" size="0.07 0.005 0.03" rgba="0.55 0.43 0.28 1" friction="1 0.01 0.001" contype="1" conaffinity="1" />
    <geom name="target_box_back_wall" type="box" pos="0.58 -0.425 0.04" size="0.07 0.005 0.03" rgba="0.55 0.43 0.28 1" friction="1 0.01 0.001" contype="1" conaffinity="1" />
    <site name="waypoint_marker" type="sphere" pos="0.5 0 0.3" size="0.012" rgba="0.2 0.6 1.0 0.4" />
    <site name="goal_marker" type="sphere" pos="0.58 -0.36 0.115" size="0.012" rgba="1.0 0.4 0.2 0.4" />
  </worldbody>
  <contact>
    <exclude body1="link0" body2="link1" />
  </contact>
  <equality>
    <joint joint1="finger_joint1" joint2="finger_joint2" polycoef="0 1 0 0 0" solref="0.005" solimp="0.95 0.99" />
  </equality>
  <tendon>
    <fixed name="split">
      <joint joint="finger_joint1" coef="0.5" />
      <joint joint="finger_joint2" coef="0.5" />
    </fixed>
  </tendon>
  <keyframe>
    <key name="home" qpos="0 0 0 -1.57079 0 1.57079 -0.7853 0.04 0.04" ctrl="0 0 0 -1.57079 0 1.57079 -0.7853 255" />
  </keyframe>
  <visual>
    <map znear="0.01" zfar="10" />
  </visual>
  <actuator>
    <position name="joint1" joint="joint1" kp="80" ctrllimited="true" ctrlrange="-2.8973 2.8973" forcelimited="true" forcerange="-87 87" />
    <position name="joint2" joint="joint2" kp="80" ctrllimited="true" ctrlrange="-1.7628 1.7628" forcelimited="true" forcerange="-87 87" />
    <position name="joint3" joint="joint3" kp="80" ctrllimited="true" ctrlrange="-2.8973 2.8973" forcelimited="true" forcerange="-87 87" />
    <position name="joint4" joint="joint4" kp="80" ctrllimited="true" ctrlrange="-3.0718 -0.0698" forcelimited="true" forcerange="-87 87" />
    <position name="joint5" joint="joint5" kp="80" ctrllimited="true" ctrlrange="-2.8973 2.8973" forcelimited="true" forcerange="-87 87" />
    <position name="joint6" joint="joint6" kp="80" ctrllimited="true" ctrlrange="-0.0175 3.7525" forcelimited="true" forcerange="-87 87" />
    <position name="joint7" joint="joint7" kp="80" ctrllimited="true" ctrlrange="-2.8973 2.8973" forcelimited="true" forcerange="-87 87" />
    <position name="finger_joint1" joint="finger_joint1" kp="2000" ctrllimited="true" ctrlrange="0 0.04" forcelimited="true" forcerange="-40 40" />
    <position name="finger_joint2" joint="finger_joint2" kp="2000" ctrllimited="true" ctrlrange="0 0.04" forcelimited="true" forcerange="-40 40" />
  </actuator>
</mujoco>