<mujocoinclude>
  <geom type="mesh" mesh="link0_0" material="off_white" contype="0" conaffinity="0" />
  <geom type="mesh" mesh="link0_1" material="black" contype="0" conaffinity="0" />
  <geom type="mesh" mesh="link0_2" material="off_white" contype="0" conaffinity="0" />
  <geom type="mesh" mesh="link0_3" material="black" contype="0" conaffinity="0" />
  <geom type="mesh" mesh="link0_4" material="off_white" contype="0" conaffinity="0" />
  <geom type="mesh" mesh="link0_5" material="black" contype="0" conaffinity="0" />
  <geom type="mesh" mesh="link0_7" material="white" contype="0" conaffinity="0" />
  <geom type="mesh" mesh="link0_8" material="white" contype="0" conaffinity="0" />
  <geom type="mesh" mesh="link0_9" material="black" contype="0" conaffinity="0" />
  <geom type="mesh" mesh="link0_10" material="off_white" contype="0" conaffinity="0" />
  <geom type="mesh" mesh="link0_11" material="white" contype="0" conaffinity="0" />
  <geom type="mesh" mesh="link0_c" contype="0" conaffinity="0" rgba="1 1 1 0" group="1" />
  <body name="panda_link1" pos="0 0 0.333">
    <inertial pos="0.003875 0.002081 -0.04762" quat="0.711549 0.00634377 -0.0131124 0.702485" mass="4.97068" diaginertia="0.707137 0.703435 0.00852456" />
    <joint name="panda_joint1" pos="0 0 0" axis="0 0 1" range="-2.8973 2.8973" actuatorfrcrange="-87 87" damping="4" armature="0" />
    <geom type="mesh" mesh="link1_v" material="white" contype="0" conaffinity="0" />
    <geom type="mesh" mesh="link1_c" rgba="1 1 1 0" group="1" />
    <body name="panda_link2" quat="0.707107 -0.707107 0 0">
      <inertial pos="-0.003141 -0.02872 0.003495" quat="-0.168175 0.828366 -0.122878 0.520027" mass="0.646926" diaginertia="0.0310326 0.0283001 0.00273425" />
      <joint name="panda_joint2" pos="0 0 0" axis="0 0 1" range="-1.7628 1.7628" actuatorfrcrange="-87 87" damping="4" armature="0" />
      <geom type="mesh" mesh="link2_v" material="white" contype="0" conaffinity="0" />
      <geom type="mesh" mesh="link2_c" rgba="1 1 1 0" group="1" />
      <body name="panda_link3" pos="0 -0.316 0" quat="0.707107 0.707107 0 0">
        <inertial pos="0.027518 0.039252 -0.066502" quat="0.662769 -0.00678331 0.252053 0.705096" mass="3.2286" diaginertia="0.0415014 0.0414793 0.00124635" />
        <joint name="panda_joint3" pos="0 0 0" axis="0 0 1" range="-2.8973 2.8973" actuatorfrcrange="-87 87" damping="4" armature="0" />
        <geom type="mesh" mesh="link3_0" material="white" contype="0" conaffinity="0" />
        <geom type="mesh" mesh="link3_1" material="white" contype="0" conaffinity="0" />
        <geom type="mesh" mesh="link3_2" material="white" contype="0" conaffinity="0" />
        <geom type="mesh" mesh="link3_3" material="black" contype="0" conaffinity="0" />
        <geom type="mesh" mesh="link3_c" rgba="1 1 1 0" group="1" />
        <body name="panda_link4" pos="0.0825 0 0" quat="0.707107 0.707107 0 0">
          <inertial pos="-0.05317 0.104419 0.027454" quat="0.65058 0.529822 -0.0962034 0.535518" mass="3.5879" diaginertia="0.0349596 0.0281483 0.0106201" />
          <joint name="panda_joint4" pos="0 0 0" axis="0 0 1" range="-3.0718 -0.0698" actuatorfrcrange="-87 87" damping="4" armature="0" />
          <geom type="mesh" mesh="link4_0" material="white" contype="0" conaffinity="0" />
          <geom type="mesh" mesh="link4_1" material="white" contype="0" conaffinity="0" />
          <geom type="mesh" mesh="link4_2" material="black" contype="0" conaffinity="0" />
          <geom type="mesh" mesh="link4_3" material="white" contype="0" conaffinity="0" />
          <geom type="mesh" mesh="link4_c" rgba="1 1 1 0" group="1" />
          <body name="panda_link5" pos="-0.0825 0.384 0" quat="0.707107 -0.707107 0 0">
            <inertial pos="-0.011953 0.041065 -0.038437" quat="0.987313 -0.0121954 0.0719187 -0.141037" mass="1.22595" diaginertia="0.0367625 0.0288531 0.00803437" />
            <joint name="panda_joint5" pos="0 0 0" axis="0 0 1" range="-2.8973 2.8973" actuatorfrcrange="-12 12" damping="4" armature="0" />
            <geom type="mesh" mesh="link5_0" material="black" contype="0" conaffinity="0" />
            <geom type="mesh" mesh="link5_1" material="white" contype="0" conaffinity="0" />
            <geom type="mesh" mesh="link5_2" material="white" contype="0" conaffinity="0" />
            <geom type="mesh" mesh="link5_c0" rgba="1 1 1 0" group="1" />
            <geom type="mesh" mesh="link5_c1" rgba="1 1 1 0" group="1" />
            <geom type="mesh" mesh="link5_c2" rgba="1 1 1 0" group="1" />
            <body name="panda_link6" quat="0.707107 0.707107 0 0">
              <inertial pos="0.060149 -0.014117 -0.010517" quat="0.101075 0.59332 0.0287227 0.798079" mass="1.66656" diaginertia="0.00584276 0.00431037 0.00159787" />
              <joint name="panda_joint6" pos="0 0 0" axis="0 0 1" range="-0.0175 3.7525" actuatorfrcrange="-12 12" damping="4" armature="0" />
              <geom type="mesh" mesh="link6_0" material="off_white" contype="0" conaffinity="0" />
              <geom type="mesh" mesh="link6_1" material="white" contype="0" conaffinity="0" />
              <geom type="mesh" mesh="link6_2" material="black" contype="0" conaffinity="0" />
              <geom type="mesh" mesh="link6_3" material="white" contype="0" conaffinity="0" />
              <geom type="mesh" mesh="link6_4" material="white" contype="0" conaffinity="0" />
              <geom type="mesh" mesh="link6_5" material="white" contype="0" conaffinity="0" />
              <geom type="mesh" mesh="link6_6" material="white" contype="0" conaffinity="0" />
              <geom type="mesh" mesh="link6_7" material="light_blue" contype="0" conaffinity="0" />
              <geom type="mesh" mesh="link6_8" material="light_blue" contype="0" conaffinity="0" />
              <geom type="mesh" mesh="link6_9" material="black" contype="0" conaffinity="0" />
              <geom type="mesh" mesh="link6_10" material="black" contype="0" conaffinity="0" />
              <geom type="mesh" mesh="link6_11" material="white" contype="0" conaffinity="0" />
              <geom type="mesh" mesh="link6_12" material="green" contype="0" conaffinity="0" />
              <geom type="mesh" mesh="link6_13" material="white" contype="0" conaffinity="0" />
              <geom type="mesh" mesh="link6_14" material="black" contype="0" conaffinity="0" />
              <geom type="mesh" mesh="link6_15" material="black" contype="0" conaffinity="0" />
              <geom type="mesh" mesh="link6_16" material="white" contype="0" conaffinity="0" />
              <geom type="mesh" mesh="link6_c" rgba="1 1 1 0" group="1" />
              <body name="panda_link7" pos="0.088 0 0" quat="0.707107 0.707107 0 0">
                <inertial pos="0.0535956 -0.00213401 0.045858" quat="0.594329 -0.0303333 0.0970674 0.797766" mass="1.46552" diaginertia="0.0155969 0.0137507 0.00943568" />
                <joint name="panda_joint7" pos="0 0 0" axis="0 0 1" range="-2.8973 2.8973" actuatorfrcrange="-12 12" damping="4" armature="0" />
                <geom type="mesh" mesh="link7_0" material="white" contype="0" conaffinity="0" />
                <geom type="mesh" mesh="link7_1" material="black" contype="0" conaffinity="0" />
                <geom type="mesh" mesh="link7_2" material="black" contype="0" conaffinity="0" />
                <geom type="mesh" mesh="link7_3" material="black" contype="0" conaffinity="0" />
                <geom type="mesh" mesh="link7_4" material="black" contype="0" conaffinity="0" />
                <geom type="mesh" mesh="link7_5" material="black" contype="0" conaffinity="0" />
                <geom type="mesh" mesh="link7_6" material="black" contype="0" conaffinity="0" />
                <geom type="mesh" mesh="link7_7" material="white" contype="0" conaffinity="0" />
                <geom type="mesh" mesh="link7_c" rgba="1 1 1 0" group="1" />
                <geom pos="0 0 0.107" quat="0.92388 0 0 -0.382683" type="mesh" mesh="hand_0" material="off_white" contype="0" conaffinity="0" />
                <geom pos="0 0 0.107" quat="0.92388 0 0 -0.382683" type="mesh" mesh="hand_1" material="black" contype="0" conaffinity="0" />
                <geom pos="0 0 0.107" quat="0.92388 0 0 -0.382683" type="mesh" mesh="hand_2" material="black" contype="0" conaffinity="0" />
                <geom pos="0 0 0.107" quat="0.92388 0 0 -0.382683" type="mesh" mesh="hand_3" material="white" contype="0" conaffinity="0" />
                <geom pos="0 0 0.107" quat="0.92388 0 0 -0.382683" type="mesh" mesh="hand_4" material="off_white" contype="0" conaffinity="0" />
                <geom pos="0 0 0.107" quat="0.92388 0 0 -0.382683" type="mesh" mesh="hand_c" rgba="1 1 1 0" group="1" />
                <body name="panda_leftfinger" pos="0 0 0.1654" quat="0.92388 0 0 -0.382683">
                  <inertial pos="0 0 0" mass="0.015" diaginertia="2.375e-06 2.375e-06 7.5e-07" />
                  <joint name="panda_finger_joint1" pos="0 0 0" axis="0 1 0" type="slide" range="0 0.04" actuatorfrcrange="-100 100" damping="100" armature="0" />
                  <geom type="mesh" mesh="finger_0" material="off_white" contype="1" conaffinity="1" />
                  <geom type="mesh" mesh="finger_1" material="black" contype="1" conaffinity="1" />
                  <geom type="box" pos="0 0.0144 0.018" size="0.0105 0.0119 0.018" rgba="1 1 1 1" group="1" />
                  <geom type="box" pos="0 0.0144 0.0448" size="0.0105 0.0119 0.0089" rgba="1 1 1 1" group="1" />
                  <geom type="box" pos="0 0.0054 0.045" size="0.00895 0.00555 0.00895" rgba="1 1 1 1" group="1" />
                </body>
                <body name="panda_rightfinger" pos="0 0 0.1654" quat="0.382683 0 0 0.92388">
                  <inertial pos="0 0 0" mass="0.015" diaginertia="2.375e-06 2.375e-06 7.5e-07" />
                  <joint name="panda_finger_joint2" pos="0 0 0" axis="0 1 0" type="slide" range="0 0.04" actuatorfrcrange="-100 100" damping="100" armature="0" />
                  <geom type="mesh" mesh="finger_0" material="off_white" contype="1" conaffinity="1" />
                  <geom type="mesh" mesh="finger_1" material="black" contype="1" conaffinity="1" />
                  <geom type="box" pos="0 0.0144 0.018" size="0.0105 0.0119 0.018" rgba="1 1 1 1" group="1" />
                  <geom type="box" pos="0 0.0144 0.0448" size="0.0105 0.0119 0.0089" rgba="1 1 1 1" group="1" />
                  <geom type="box" pos="0 0.0054 0.045" size="0.00895 0.00555 0.00895" rgba="1 1 1 1" group="1" />
                </body>
              </body>
            </body>
          </body>
        </body>
      </body>
    </body>
  </body>
</mujocoinclude>